<?xml version="1.0"?>
<robot name="mechanical_arm">
  <!-- Base link -->
  <link name="base_link">
    <visual>
      <geometry>
        <box size="0.5 0.5 0.1"/>
      </geometry>
      <material>
        <color rgba="0.8 0.8 0.8 1.0"/>
      </material>
    </visual>
  </link>

  <!-- Arm link -->
  <link name="arm_link">
    <visual>
      <geometry>
        <box size="0.1 0.1 1.0"/>
      </geometry>
      <material>
        <color rgba="0.0 0.0 0.8 1.0"/>
      </material>
    </visual>
  </link>

  <!-- Joint -->
  <joint name="arm_joint" type="revolute">
    <parent link="base_link"/>
    <child link="arm_link"/>
    <origin xyz="0 0 0.05" rpy="0 0 0"/>
    <axis xyz="0 1 0"/>
    <limit effort="10.0" lower="-1.57" upper="1.57" velocity="1.0"/>
  </joint>
</robot>
